{"uuid": "621cfa3c-eb25-4f1d-b7dd-26e75378c491", "children": ["268d395c-cb5d-45fb-8af8-64cdffb30efd"], "befores": [{"name": "appium_driver", "status": "broken", "statusDetails": {"message": "selenium.common.exceptions.WebDriverException: Message: An unknown server-side error occurred while processing the command. Original error: Could not find a connected Android device in 20278ms.\nStacktrace:\nUnknownError: An unknown server-side error occurred while processing the command. Original error: Could not find a connected Android device in 20278ms.\n    at getResponseForW3CError (C:\\Program Files\\Appium Server GUI\\resources\\app\\node_modules\\appium\\node_modules\\appium-base-driver\\lib\\protocol\\errors.js:804:9)\n    at asyncHandler (C:\\Program Files\\Appium Server GUI\\resources\\app\\node_modules\\appium\\node_modules\\appium-base-driver\\lib\\protocol\\protocol.js:380:37)\n", "trace": "  File \"C:\\Users\\aksha\\PycharmProjects\\AppiumSandbox\\venv\\Lib\\site-packages\\pluggy\\_callers.py\", line 102, in _multicall\n    res = hook_impl.function(*args)\n          ^^^^^^^^^^^^^^^^^^^^^^^^^\n  File \"C:\\Users\\aksha\\PycharmProjects\\AppiumSandbox\\venv\\Lib\\site-packages\\_pytest\\fixtures.py\", line 1123, in pytest_fixture_setup\n    result = call_fixture_func(fixturefunc, request, kwargs)\n             ^^^^^^^^^^^^^^^^^^^^^^^^^^^^^^^^^^^^^^^^^^^^^^^\n  File \"C:\\Users\\aksha\\PycharmProjects\\AppiumSandbox\\venv\\Lib\\site-packages\\_pytest\\fixtures.py\", line 895, in call_fixture_func\n    fixture_result = next(generator)\n                     ^^^^^^^^^^^^^^^\n  File \"C:\\Users\\aksha\\PycharmProjects\\AppiumSandbox\\main.py\", line 36, in appium_driver\n    driver = webdriver.Remote(\"http://127.0.0.1:4723/wd/hub\", options=options)\n             ^^^^^^^^^^^^^^^^^^^^^^^^^^^^^^^^^^^^^^^^^^^^^^^^^^^^^^^^^^^^^^^^^\n  File \"C:\\Users\\aksha\\PycharmProjects\\AppiumSandbox\\venv\\Lib\\site-packages\\appium\\webdriver\\webdriver.py\", line 229, in __init__\n    super().__init__(\n  File \"C:\\Users\\aksha\\PycharmProjects\\AppiumSandbox\\venv\\Lib\\site-packages\\selenium\\webdriver\\remote\\webdriver.py\", line 208, in __init__\n    self.start_session(capabilities)\n  File \"C:\\Users\\aksha\\PycharmProjects\\AppiumSandbox\\venv\\Lib\\site-packages\\appium\\webdriver\\webdriver.py\", line 321, in start_session\n    response = self.execute(RemoteCommand.NEW_SESSION, w3c_caps)\n               ^^^^^^^^^^^^^^^^^^^^^^^^^^^^^^^^^^^^^^^^^^^^^^^^^\n  File \"C:\\Users\\aksha\\PycharmProjects\\AppiumSandbox\\venv\\Lib\\site-packages\\selenium\\webdriver\\remote\\webdriver.py\", line 347, in execute\n    self.error_handler.check_response(response)\n  File \"C:\\Users\\aksha\\PycharmProjects\\AppiumSandbox\\venv\\Lib\\site-packages\\selenium\\webdriver\\remote\\errorhandler.py\", line 229, in check_response\n    raise exception_class(message, screen, stacktrace)\n"}, "start": 1707226876698, "stop": 1707226897310}], "start": 1707226876698, "stop": 1707226897783}